{"level":"error","message":"❌ Error synchronizing database: cache lookup failed for attribute 1 of relation 1228803","name":"SequelizeDatabaseError","original":{"code":"XX000","file":"lsyscache.c","length":117,"line":"982","name":"error","routine":"get_attoptions","severity":"ERROR","sql":"SELECT i.relname AS name, ix.indisprimary AS primary, ix.indisunique AS unique, ix.indkey AS indkey, array_agg(a.attnum) as column_indexes, array_agg(a.attname) AS column_names, pg_get_indexdef(ix.indexrelid) AS definition FROM pg_class t, pg_class i, pg_index ix, pg_attribute a WHERE t.oid = ix.indrelid AND i.oid = ix.indexrelid AND a.attrelid = t.oid AND t.relkind = 'r' and t.relname = 'categories' GROUP BY i.relname, ix.indexrelid, ix.indisprimary, ix.indisunique, ix.indkey ORDER BY i.relname;"},"parameters":{},"parent":{"code":"XX000","file":"lsyscache.c","length":117,"line":"982","name":"error","routine":"get_attoptions","severity":"ERROR","sql":"SELECT i.relname AS name, ix.indisprimary AS primary, ix.indisunique AS unique, ix.indkey AS indkey, array_agg(a.attnum) as column_indexes, array_agg(a.attname) AS column_names, pg_get_indexdef(ix.indexrelid) AS definition FROM pg_class t, pg_class i, pg_index ix, pg_attribute a WHERE t.oid = ix.indrelid AND i.oid = ix.indexrelid AND a.attrelid = t.oid AND t.relkind = 'r' and t.relname = 'categories' GROUP BY i.relname, ix.indexrelid, ix.indisprimary, ix.indisunique, ix.indkey ORDER BY i.relname;"},"sql":"SELECT i.relname AS name, ix.indisprimary AS primary, ix.indisunique AS unique, ix.indkey AS indkey, array_agg(a.attnum) as column_indexes, array_agg(a.attname) AS column_names, pg_get_indexdef(ix.indexrelid) AS definition FROM pg_class t, pg_class i, pg_index ix, pg_attribute a WHERE t.oid = ix.indrelid AND i.oid = ix.indexrelid AND a.attrelid = t.oid AND t.relkind = 'r' and t.relname = 'categories' GROUP BY i.relname, ix.indexrelid, ix.indisprimary, ix.indisunique, ix.indkey ORDER BY i.relname;","stack":"Error\n    at Query.run (C:\\Users\\atoda\\Documents\\Money_Mate\\BackEnd\\node_modules\\sequelize\\src\\dialects\\postgres\\query.js:76:25)\n    at C:\\Users\\atoda\\Documents\\Money_Mate\\BackEnd\\node_modules\\sequelize\\src\\sequelize.js:650:28\n    at processTicksAndRejections (node:internal/process/task_queues:95:5)\n    at async PostgresQueryInterface.showIndex (C:\\Users\\atoda\\Documents\\Money_Mate\\BackEnd\\node_modules\\sequelize\\src\\dialects\\abstract\\query-interface.js:600:12)\n    at async Function.sync (C:\\Users\\atoda\\Documents\\Money_Mate\\BackEnd\\node_modules\\sequelize\\src\\model.js:1413:29)\n    at async Sequelize.sync (C:\\Users\\atoda\\Documents\\Money_Mate\\BackEnd\\node_modules\\sequelize\\src\\sequelize.js:825:9)","timestamp":"2025-04-18T17:23:40.436Z"}
{"level":"error","message":"❌ Error synchronizing database: column \"updated_at\" of relation \"financial_insights\" contains null values","name":"SequelizeDatabaseError","original":{"code":"23502","column":"updated_at","file":"tablecmds.c","length":176,"line":"6279","name":"error","routine":"ATRewriteTable","schema":"public","severity":"ERROR","sql":"ALTER TABLE \"public\".\"financial_insights\" ADD COLUMN \"updated_at\" TIMESTAMP WITH TIME ZONE NOT NULL;","table":"financial_insights"},"parameters":{},"parent":{"code":"23502","column":"updated_at","file":"tablecmds.c","length":176,"line":"6279","name":"error","routine":"ATRewriteTable","schema":"public","severity":"ERROR","sql":"ALTER TABLE \"public\".\"financial_insights\" ADD COLUMN \"updated_at\" TIMESTAMP WITH TIME ZONE NOT NULL;","table":"financial_insights"},"sql":"ALTER TABLE \"public\".\"financial_insights\" ADD COLUMN \"updated_at\" TIMESTAMP WITH TIME ZONE NOT NULL;","stack":"Error\n    at Query.run (C:\\Users\\atoda\\Documents\\Money_Mate\\BackEnd\\node_modules\\sequelize\\src\\dialects\\postgres\\query.js:76:25)\n    at C:\\Users\\atoda\\Documents\\Money_Mate\\BackEnd\\node_modules\\sequelize\\src\\sequelize.js:650:28\n    at processTicksAndRejections (node:internal/process/task_queues:95:5)\n    at async PostgresQueryInterface.addColumn (C:\\Users\\atoda\\Documents\\Money_Mate\\BackEnd\\node_modules\\sequelize\\src\\dialects\\abstract\\query-interface.js:430:12)\n    at async Function.sync (C:\\Users\\atoda\\Documents\\Money_Mate\\BackEnd\\node_modules\\sequelize\\src\\model.js:1373:11)\n    at async Sequelize.sync (C:\\Users\\atoda\\Documents\\Money_Mate\\BackEnd\\node_modules\\sequelize\\src\\sequelize.js:825:9)","timestamp":"2025-04-18T17:24:01.083Z"}
{"constraint":"transactions_user_id_fkey","level":"error","message":"❌ Error synchronizing database: Unknown constraint error","name":"SequelizeUnknownConstraintError","original":{"code":"42704","file":"tablecmds.c","length":150,"line":"12607","name":"error","routine":"ATExecDropConstraint","severity":"ERROR","sql":"ALTER TABLE \"transactions\" DROP CONSTRAINT \"transactions_user_id_fkey\""},"parameters":{},"parent":{"code":"42704","file":"tablecmds.c","length":150,"line":"12607","name":"error","routine":"ATExecDropConstraint","severity":"ERROR","sql":"ALTER TABLE \"transactions\" DROP CONSTRAINT \"transactions_user_id_fkey\""},"sql":"ALTER TABLE \"transactions\" DROP CONSTRAINT \"transactions_user_id_fkey\"","stack":"Error\n    at Query.run (C:\\Users\\atoda\\Documents\\Money_Mate\\BackEnd\\node_modules\\sequelize\\src\\dialects\\postgres\\query.js:76:25)\n    at C:\\Users\\atoda\\Documents\\Money_Mate\\BackEnd\\node_modules\\sequelize\\src\\sequelize.js:650:28\n    at processTicksAndRejections (node:internal/process/task_queues:95:5)\n    at async Function.sync (C:\\Users\\atoda\\Documents\\Money_Mate\\BackEnd\\node_modules\\sequelize\\src\\model.js:1402:17)\n    at async Sequelize.sync (C:\\Users\\atoda\\Documents\\Money_Mate\\BackEnd\\node_modules\\sequelize\\src\\sequelize.js:825:9)","table":"transactions","timestamp":"2025-04-18T17:33:06.684Z"}
{"level":"error","message":"[process_insights.py Error] Traceback (most recent call last):\r\n  File \"C:\\Users\\atoda\\Documents\\Money_Mate\\data_processing\\scripts\\process_insights.py\", line 349, in <module>","timestamp":"2025-04-18T17:33:29.514Z"}
{"level":"error","message":"[process_insights.py Error] process_insights()","timestamp":"2025-04-18T17:33:29.514Z"}
{"level":"error","message":"[process_insights.py Error] ^^^^^^^^^^^^^^^^^^","timestamp":"2025-04-18T17:33:29.515Z"}
{"level":"error","message":"[process_insights.py Error] File \"C:\\Users\\atoda\\Documents\\Money_Mate\\data_processing\\scripts\\process_insights.py\", line 334, in process_insights","timestamp":"2025-04-18T17:33:29.515Z"}
{"level":"error","message":"[process_insights.py Error] save_insights_to_db(all_insights)\r\n  File \"C:\\Users\\atoda\\Documents\\Money_Mate\\data_processing\\scripts\\process_insights.py\", line 265, in save_insights_to_db","timestamp":"2025-04-18T17:33:29.515Z"}
{"level":"error","message":"[process_insights.py Error] execute_values(cur, insert_query, data)\r\n  File \"C:\\Users\\atoda\\Documents\\Money_Mate\\venv\\Lib\\site-packages\\psycopg2\\extras.py\", line 1299, in execute_values","timestamp":"2025-04-18T17:33:29.516Z"}
{"level":"error","message":"[process_insights.py Error] cur.execute(b''.join(parts))","timestamp":"2025-04-18T17:33:29.553Z"}
{"level":"error","message":"[process_insights.py Error] psycopg2.errors.NotNullViolation: null value in column \"updated_at\" of relation \"financial_insights\" violates not-null constraint\r\nDETAIL:  Failing row contains (f75afd49-51c9-4f6c-8a79-9f58fb07da89, Monthly Spend Summary, 2023-04, null, null, 765.97, null, null, null, null, 839a60a1-91b1-4d97-a935-5724cf3463bb, 2025-04-18 23:03:26.803838+00, null, null, null, null, null).","timestamp":"2025-04-18T17:33:29.553Z"}
{"level":"error","message":"❌ process_insights.py failed with code 1","timestamp":"2025-04-18T17:33:29.769Z"}
{"level":"error","message":"[process_insights.py Error] Traceback (most recent call last):\r\n  File \"C:\\Users\\atoda\\Documents\\Money_Mate\\data_processing\\scripts\\process_insights.py\", line 349, in <module>\r\n    process_insights() \r\n    ^^^^^^^^^^^^^^^^^^\r\n  File \"C:\\Users\\atoda\\Documents\\Money_Mate\\data_processing\\scripts\\process_insights.py\", line 334, in process_insights\r\n    save_insights_to_db(all_insights)\r\n  File \"C:\\Users\\atoda\\Documents\\Money_Mate\\data_processing\\scripts\\process_insights.py\", line 265, in save_insights_to_db","timestamp":"2025-04-18T17:34:07.354Z"}
{"level":"error","message":"[process_insights.py Error] execute_values(cur, insert_query, data)\r\n  File \"C:\\Users\\atoda\\Documents\\Money_Mate\\venv\\Lib\\site-packages\\psycopg2\\extras.py\", line 1299, in execute_values","timestamp":"2025-04-18T17:34:07.354Z"}
{"level":"error","message":"[process_insights.py Error] cur.execute(b''.join(parts))\r\npsycopg2.errors.InvalidTextRepresentation: invalid input value for enum enum_financial_insights_insight_type: \"Monthly Spend Summary\"\r\nLINE 5: ...   VALUES ('f17d3d19-c5fe-4aff-bece-0fbc96ddd92d','Monthly S...\r\n                                                             ^","timestamp":"2025-04-18T17:34:07.355Z"}
{"level":"error","message":"❌ process_insights.py failed with code 1","timestamp":"2025-04-18T17:34:07.579Z"}
{"level":"error","message":"[process_insights.py Error] Traceback (most recent call last):\r\n  File \"C:\\Users\\atoda\\Documents\\Money_Mate\\data_processing\\scripts\\process_insights.py\", line 349, in <module>","timestamp":"2025-04-18T17:37:42.240Z"}
{"level":"error","message":"[process_insights.py Error] process_insights()","timestamp":"2025-04-18T17:37:42.241Z"}
{"level":"error","message":"[process_insights.py Error] ^^^^^^^^^^^^^^^^^^","timestamp":"2025-04-18T17:37:42.242Z"}
{"level":"error","message":"[process_insights.py Error] File \"C:\\Users\\atoda\\Documents\\Money_Mate\\data_processing\\scripts\\process_insights.py\", line 328, in process_insights\r\n    alerts = generate_alerts(user_insights, user_id)\r\n             ^^^^^^^^^^^^^^^^^^^^^^^^^^^^^^^^^^^^^^^\r\n  File \"C:\\Users\\atoda\\Documents\\Money_Mate\\data_processing\\scripts\\process_insights.py\", line 225, in generate_alerts","timestamp":"2025-04-18T17:37:42.243Z"}
{"level":"error","message":"[process_insights.py Error] if insight['balance'] < 1000:  # Low balance threshold\r\n       ^^^^^^^^^^^^^^^^^^^^^^^^^\r\nTypeError: '<' not supported between instances of 'NoneType' and 'int'","timestamp":"2025-04-18T17:37:42.243Z"}
{"level":"error","message":"❌ process_insights.py failed with code 1","timestamp":"2025-04-18T17:37:42.556Z"}
{"level":"error","message":"[process_insights.py Error] Traceback (most recent call last):\r\n  File \"C:\\Users\\atoda\\Documents\\Money_Mate\\data_processing\\scripts\\process_insights.py\", line 349, in <module>\r\n    process_insights() \r\n    ^^^^^^^^^^^^^^^^^^\r\n  File \"C:\\Users\\atoda\\Documents\\Money_Mate\\data_processing\\scripts\\process_insights.py\", line 328, in process_insights","timestamp":"2025-04-18T17:37:59.391Z"}
{"level":"error","message":"[process_insights.py Error] alerts = generate_alerts(user_insights, user_id)\r\n             ^^^^^^^^^^^^^^^^^^^^^^^^^^^^^^^^^^^^^^^\r\n  File \"C:\\Users\\atoda\\Documents\\Money_Mate\\data_processing\\scripts\\process_insights.py\", line 225, in generate_alerts","timestamp":"2025-04-18T17:37:59.391Z"}
{"level":"error","message":"[process_insights.py Error] if insight['balance'] < 1000:  # Low balance threshold\r\n       ^^^^^^^^^^^^^^^^^^^^^^^^^\r\nTypeError: '<' not supported between instances of 'NoneType' and 'int'","timestamp":"2025-04-18T17:37:59.392Z"}
{"level":"error","message":"❌ process_insights.py failed with code 1","timestamp":"2025-04-18T17:37:59.835Z"}
{"constraint":"budget_categories_budget_id_fkey","level":"error","message":"❌ Error synchronizing database: Unknown constraint error","name":"SequelizeUnknownConstraintError","original":{"code":"42704","file":"tablecmds.c","length":162,"line":"12607","name":"error","routine":"ATExecDropConstraint","severity":"ERROR","sql":"ALTER TABLE \"budget_categories\" DROP CONSTRAINT \"budget_categories_budget_id_fkey\""},"parameters":{},"parent":{"code":"42704","file":"tablecmds.c","length":162,"line":"12607","name":"error","routine":"ATExecDropConstraint","severity":"ERROR","sql":"ALTER TABLE \"budget_categories\" DROP CONSTRAINT \"budget_categories_budget_id_fkey\""},"sql":"ALTER TABLE \"budget_categories\" DROP CONSTRAINT \"budget_categories_budget_id_fkey\"","stack":"Error\n    at Query.run (C:\\Users\\atoda\\Documents\\Money_Mate\\BackEnd\\node_modules\\sequelize\\src\\dialects\\postgres\\query.js:76:25)\n    at C:\\Users\\atoda\\Documents\\Money_Mate\\BackEnd\\node_modules\\sequelize\\src\\sequelize.js:650:28\n    at processTicksAndRejections (node:internal/process/task_queues:95:5)\n    at async Function.sync (C:\\Users\\atoda\\Documents\\Money_Mate\\BackEnd\\node_modules\\sequelize\\src\\model.js:1402:17)\n    at async Sequelize.sync (C:\\Users\\atoda\\Documents\\Money_Mate\\BackEnd\\node_modules\\sequelize\\src\\sequelize.js:825:9)","table":"budget_categories","timestamp":"2025-04-18T17:40:22.695Z"}
{"level":"error","message":"[process_insights.py Error] Traceback (most recent call last):\r\n  File \"C:\\Users\\atoda\\Documents\\Money_Mate\\data_processing\\scripts\\process_insights.py\", line 366, in <module>\r\n    process_insights() \r\n    ^^^^^^^^^^^^^^^^^^\r\n  File \"C:\\Users\\atoda\\Documents\\Money_Mate\\data_processing\\scripts\\process_insights.py\", line 351, in process_insights\r\n    save_insights_to_db(all_insights)\r\n  File \"C:\\Users\\atoda\\Documents\\Money_Mate\\data_processing\\scripts\\process_insights.py\", line 282, in save_insights_to_db","timestamp":"2025-04-18T17:40:42.122Z"}
{"level":"error","message":"[process_insights.py Error] execute_values(cur, insert_query, data)\r\n  File \"C:\\Users\\atoda\\Documents\\Money_Mate\\venv\\Lib\\site-packages\\psycopg2\\extras.py\", line 1299, in execute_values","timestamp":"2025-04-18T17:40:42.123Z"}
{"level":"error","message":"[process_insights.py Error] cur.execute(b''.join(parts))\r\npsycopg2.errors.NotNullViolation: null value in column \"updated_at\" of relation \"financial_insights\" violates not-null constraint\r\nDETAIL:  Failing row contains (c0a63472-3667-4663-83c9-9f7efa6d23c3, comparison, 2023-04, null, null, 765.97, null, null, null, null, 839a60a1-91b1-4d97-a935-5724cf3463bb, 2025-04-18 23:10:40.964329+00, null, null, null, null, null, null, null, f, null, f, null).","timestamp":"2025-04-18T17:40:42.124Z"}
{"level":"error","message":"❌ process_insights.py failed with code 1","timestamp":"2025-04-18T17:40:42.408Z"}
{"level":"error","message":"[process_insights.py Error] Traceback (most recent call last):\r\n  File \"C:\\Users\\atoda\\Documents\\Money_Mate\\data_processing\\scripts\\process_insights.py\", line 366, in <module>\r\n    process_insights() \r\n    ^^^^^^^^^^^^^^^^^^\r\n  File \"C:\\Users\\atoda\\Documents\\Money_Mate\\data_processing\\scripts\\process_insights.py\", line 351, in process_insights","timestamp":"2025-04-18T17:41:01.401Z"}
{"level":"error","message":"[process_insights.py Error] save_insights_to_db(all_insights)\r\n  File \"C:\\Users\\atoda\\Documents\\Money_Mate\\data_processing\\scripts\\process_insights.py\", line 282, in save_insights_to_db\r\n    execute_values(cur, insert_query, data)\r\n  File \"C:\\Users\\atoda\\Documents\\Money_Mate\\venv\\Lib\\site-packages\\psycopg2\\extras.py\", line 1299, in execute_values","timestamp":"2025-04-18T17:41:01.402Z"}
{"level":"error","message":"[process_insights.py Error] cur.execute(b''.join(parts))","timestamp":"2025-04-18T17:41:01.402Z"}
{"level":"error","message":"[process_insights.py Error] psycopg2.errors.NotNullViolation: null value in column \"updated_at\" of relation \"financial_insights\" violates not-null constraint\r\nDETAIL:  Failing row contains (ad5df1de-50a9-4b2f-8d8c-4356551c2c74, comparison, 2023-04, null, null, 765.97, null, null, null, null, 839a60a1-91b1-4d97-a935-5724cf3463bb, 2025-04-18 23:11:00.112094+00, null, null, null, null, null, null, null, f, null, f, null).","timestamp":"2025-04-18T17:41:01.403Z"}
{"level":"error","message":"❌ process_insights.py failed with code 1","timestamp":"2025-04-18T17:41:01.696Z"}
{"level":"error","message":"[process_insights.py Error] C:\\Users\\atoda\\Documents\\Money_Mate\\data_processing\\scripts\\process_insights.py:252: UserWarning: pandas only supports SQLAlchemy connectable (engine/connection) or database string URI or sqlite3 DBAPI2 connection. Other DBAPI2 objects are not tested. Please consider using SQLAlchemy.\r\n  transactions = pd.read_sql(\"SELECT * FROM transactions\", conn)","timestamp":"2025-04-18T18:08:00.521Z"}
{"level":"error","message":"[process_insights.py Error] C:\\Users\\atoda\\Documents\\Money_Mate\\data_processing\\scripts\\process_insights.py:252: UserWarning: pandas only supports SQLAlchemy connectable (engine/connection) or database string URI or sqlite3 DBAPI2 connection. Other DBAPI2 objects are not tested. Please consider using SQLAlchemy.\r\n  transactions = pd.read_sql(\"SELECT * FROM transactions\", conn)","timestamp":"2025-04-18T18:08:00.521Z"}
{"level":"error","message":"[process_insights.py Error] C:\\Users\\atoda\\Documents\\Money_Mate\\data_processing\\scripts\\process_insights.py:253: UserWarning: pandas only supports SQLAlchemy connectable (engine/connection) or database string URI or sqlite3 DBAPI2 connection. Other DBAPI2 objects are not tested. Please consider using SQLAlchemy.\r\n  categories = pd.read_sql(\"SELECT * FROM categories\", conn)","timestamp":"2025-04-18T18:08:01.743Z"}
{"level":"error","message":"[process_insights.py Error] C:\\Users\\atoda\\Documents\\Money_Mate\\data_processing\\scripts\\process_insights.py:253: UserWarning: pandas only supports SQLAlchemy connectable (engine/connection) or database string URI or sqlite3 DBAPI2 connection. Other DBAPI2 objects are not tested. Please consider using SQLAlchemy.\r\n  categories = pd.read_sql(\"SELECT * FROM categories\", conn)","timestamp":"2025-04-18T18:08:01.743Z"}
{"level":"error","message":"[process_insights.py Error] C:\\Users\\atoda\\Documents\\Money_Mate\\data_processing\\scripts\\process_insights.py:254: UserWarning: pandas only supports SQLAlchemy connectable (engine/connection) or database string URI or sqlite3 DBAPI2 connection. Other DBAPI2 objects are not tested. Please consider using SQLAlchemy.\r\n  users = pd.read_sql(\"SELECT * FROM users\", conn)","timestamp":"2025-04-18T18:08:02.050Z"}
{"level":"error","message":"[process_insights.py Error] C:\\Users\\atoda\\Documents\\Money_Mate\\data_processing\\scripts\\process_insights.py:254: UserWarning: pandas only supports SQLAlchemy connectable (engine/connection) or database string URI or sqlite3 DBAPI2 connection. Other DBAPI2 objects are not tested. Please consider using SQLAlchemy.\r\n  users = pd.read_sql(\"SELECT * FROM users\", conn)","timestamp":"2025-04-18T18:08:02.052Z"}
{"level":"error","message":"[process_insights.py Error] C:\\Users\\atoda\\Documents\\Money_Mate\\data_processing\\scripts\\process_insights.py:148: UserWarning: Converting to PeriodArray/Index representation will drop timezone information.\r\n  transactions['month'] = transactions['transaction_date'].dt.to_period('M')","timestamp":"2025-04-18T18:08:02.390Z"}
{"level":"error","message":"[process_insights.py Error] C:\\Users\\atoda\\Documents\\Money_Mate\\data_processing\\scripts\\process_insights.py:148: UserWarning: Converting to PeriodArray/Index representation will drop timezone information.\r\n  transactions['month'] = transactions['transaction_date'].dt.to_period('M')","timestamp":"2025-04-18T18:08:02.391Z"}
{"level":"error","message":"[process_insights.py Error] C:\\Users\\atoda\\Documents\\Money_Mate\\data_processing\\scripts\\process_insights.py:92: UserWarning: Converting to PeriodArray/Index representation will drop timezone information.\r\n  transactions['month'] = transactions['transaction_date'].dt.to_period('M')","timestamp":"2025-04-18T18:08:02.644Z"}
{"level":"error","message":"[process_insights.py Error] C:\\Users\\atoda\\Documents\\Money_Mate\\data_processing\\scripts\\process_insights.py:92: UserWarning: Converting to PeriodArray/Index representation will drop timezone information.\r\n  transactions['month'] = transactions['transaction_date'].dt.to_period('M')","timestamp":"2025-04-18T18:08:02.645Z"}
{"level":"error","message":"[process_insights.py Error] Traceback (most recent call last):\r\n  File \"C:\\Users\\atoda\\Documents\\Money_Mate\\data_processing\\scripts\\process_insights.py\", line 297, in <module>","timestamp":"2025-04-18T18:08:05.793Z"}
{"level":"error","message":"[process_insights.py Error] process_insights()","timestamp":"2025-04-18T18:08:05.793Z"}
{"level":"error","message":"[process_insights.py Error] ^^^^^^^^^^^^^^^^^^\r\n  File \"C:\\Users\\atoda\\Documents\\Money_Mate\\data_processing\\scripts\\process_insights.py\", line 282, in process_insights","timestamp":"2025-04-18T18:08:05.794Z"}
{"level":"error","message":"[process_insights.py Error] save_insights_to_db(all_insights)","timestamp":"2025-04-18T18:08:05.795Z"}
{"level":"error","message":"[process_insights.py Error] File \"C:\\Users\\atoda\\Documents\\Money_Mate\\data_processing\\scripts\\process_insights.py\", line 234, in save_insights_to_db\r\n    execute_values(cur, insert_query, data)","timestamp":"2025-04-18T18:08:05.795Z"}
{"level":"error","message":"[process_insights.py Error] File \"C:\\Users\\atoda\\Documents\\Money_Mate\\venv\\Lib\\site-packages\\psycopg2\\extras.py\", line 1299, in execute_values","timestamp":"2025-04-18T18:08:05.796Z"}
{"level":"error","message":"[process_insights.py Error] cur.execute(b''.join(parts))","timestamp":"2025-04-18T18:08:05.797Z"}
{"level":"error","message":"[process_insights.py Error] psycopg2.errors.InvalidTextRepresentation: invalid input value for enum enum_financial_insights_insight_type: \"Monthly Spend Summary\"\r\nLINE 5: ...   VALUES ('0d124634-1078-4509-ad37-beaf0eb3823e','Monthly S...\r\n                                                             ^","timestamp":"2025-04-18T18:08:05.797Z"}
{"level":"error","message":"[process_insights.py Error] Traceback (most recent call last):\r\n  File \"C:\\Users\\atoda\\Documents\\Money_Mate\\data_processing\\scripts\\process_insights.py\", line 297, in <module>","timestamp":"2025-04-18T18:08:06.039Z"}
{"level":"error","message":"[process_insights.py Error] process_insights() \r\n    ^^^^^^^^^^^^^^^^^^\r\n  File \"C:\\Users\\atoda\\Documents\\Money_Mate\\data_processing\\scripts\\process_insights.py\", line 282, in process_insights","timestamp":"2025-04-18T18:08:06.042Z"}
{"level":"error","message":"[process_insights.py Error] save_insights_to_db(all_insights)\r\n  File \"C:\\Users\\atoda\\Documents\\Money_Mate\\data_processing\\scripts\\process_insights.py\", line 234, in save_insights_to_db","timestamp":"2025-04-18T18:08:06.044Z"}
{"level":"error","message":"[process_insights.py Error] execute_values(cur, insert_query, data)\r\n  File \"C:\\Users\\atoda\\Documents\\Money_Mate\\venv\\Lib\\site-packages\\psycopg2\\extras.py\", line 1299, in execute_values","timestamp":"2025-04-18T18:08:06.045Z"}
{"level":"error","message":"[process_insights.py Error] cur.execute(b''.join(parts))","timestamp":"2025-04-18T18:08:06.046Z"}
{"level":"error","message":"[process_insights.py Error] psycopg2.errors.InvalidTextRepresentation: invalid input value for enum enum_financial_insights_insight_type: \"Monthly Spend Summary\"\r\nLINE 5: ...   VALUES ('e835ff29-ed93-45a8-9973-80e91bee7a13','Monthly S...\r\n                                                             ^","timestamp":"2025-04-18T18:08:06.046Z"}
{"level":"error","message":"❌ process_insights.py failed with code 1","timestamp":"2025-04-18T18:08:06.355Z"}
{"level":"error","message":"❌ process_insights.py failed with code 1","timestamp":"2025-04-18T18:08:06.674Z"}
{"level":"error","message":"[process_insights.py Error] C:\\Users\\atoda\\Documents\\Money_Mate\\data_processing\\scripts\\process_insights.py:252: UserWarning: pandas only supports SQLAlchemy connectable (engine/connection) or database string URI or sqlite3 DBAPI2 connection. Other DBAPI2 objects are not tested. Please consider using SQLAlchemy.\r\n  transactions = pd.read_sql(\"SELECT * FROM transactions\", conn)","timestamp":"2025-04-18T18:12:52.374Z"}
{"level":"error","message":"[process_insights.py Error] C:\\Users\\atoda\\Documents\\Money_Mate\\data_processing\\scripts\\process_insights.py:252: UserWarning: pandas only supports SQLAlchemy connectable (engine/connection) or database string URI or sqlite3 DBAPI2 connection. Other DBAPI2 objects are not tested. Please consider using SQLAlchemy.\r\n  transactions = pd.read_sql(\"SELECT * FROM transactions\", conn)","timestamp":"2025-04-18T18:12:52.374Z"}
{"level":"error","message":"[process_insights.py Error] C:\\Users\\atoda\\Documents\\Money_Mate\\data_processing\\scripts\\process_insights.py:253: UserWarning: pandas only supports SQLAlchemy connectable (engine/connection) or database string URI or sqlite3 DBAPI2 connection. Other DBAPI2 objects are not tested. Please consider using SQLAlchemy.\r\n  categories = pd.read_sql(\"SELECT * FROM categories\", conn)","timestamp":"2025-04-18T18:12:53.682Z"}
{"level":"error","message":"[process_insights.py Error] C:\\Users\\atoda\\Documents\\Money_Mate\\data_processing\\scripts\\process_insights.py:253: UserWarning: pandas only supports SQLAlchemy connectable (engine/connection) or database string URI or sqlite3 DBAPI2 connection. Other DBAPI2 objects are not tested. Please consider using SQLAlchemy.\r\n  categories = pd.read_sql(\"SELECT * FROM categories\", conn)","timestamp":"2025-04-18T18:12:53.682Z"}
{"level":"error","message":"[process_insights.py Error] C:\\Users\\atoda\\Documents\\Money_Mate\\data_processing\\scripts\\process_insights.py:254: UserWarning: pandas only supports SQLAlchemy connectable (engine/connection) or database string URI or sqlite3 DBAPI2 connection. Other DBAPI2 objects are not tested. Please consider using SQLAlchemy.\r\n  users = pd.read_sql(\"SELECT * FROM users\", conn)","timestamp":"2025-04-18T18:12:54.035Z"}
{"level":"error","message":"[process_insights.py Error] C:\\Users\\atoda\\Documents\\Money_Mate\\data_processing\\scripts\\process_insights.py:254: UserWarning: pandas only supports SQLAlchemy connectable (engine/connection) or database string URI or sqlite3 DBAPI2 connection. Other DBAPI2 objects are not tested. Please consider using SQLAlchemy.\r\n  users = pd.read_sql(\"SELECT * FROM users\", conn)","timestamp":"2025-04-18T18:12:54.035Z"}
{"level":"error","message":"[process_insights.py Error] C:\\Users\\atoda\\Documents\\Money_Mate\\data_processing\\scripts\\process_insights.py:148: UserWarning: Converting to PeriodArray/Index representation will drop timezone information.\r\n  transactions['month'] = transactions['transaction_date'].dt.to_period('M')","timestamp":"2025-04-18T18:12:54.338Z"}
{"level":"error","message":"[process_insights.py Error] C:\\Users\\atoda\\Documents\\Money_Mate\\data_processing\\scripts\\process_insights.py:148: UserWarning: Converting to PeriodArray/Index representation will drop timezone information.\r\n  transactions['month'] = transactions['transaction_date'].dt.to_period('M')","timestamp":"2025-04-18T18:12:54.338Z"}
{"level":"error","message":"[process_insights.py Error] C:\\Users\\atoda\\Documents\\Money_Mate\\data_processing\\scripts\\process_insights.py:92: UserWarning: Converting to PeriodArray/Index representation will drop timezone information.\r\n  transactions['month'] = transactions['transaction_date'].dt.to_period('M')","timestamp":"2025-04-18T18:12:54.372Z"}
{"level":"error","message":"[process_insights.py Error] C:\\Users\\atoda\\Documents\\Money_Mate\\data_processing\\scripts\\process_insights.py:92: UserWarning: Converting to PeriodArray/Index representation will drop timezone information.\r\n  transactions['month'] = transactions['transaction_date'].dt.to_period('M')","timestamp":"2025-04-18T18:12:54.372Z"}
{"level":"error","message":"[process_insights.py Error] Traceback (most recent call last):\r\n  File \"C:\\Users\\atoda\\Documents\\Money_Mate\\data_processing\\scripts\\process_insights.py\", line 297, in <module>","timestamp":"2025-04-18T18:12:57.393Z"}
{"level":"error","message":"[process_insights.py Error] process_insights() \r\n    ^^^^^^^^^^^^^^^^^^\r\n  File \"C:\\Users\\atoda\\Documents\\Money_Mate\\data_processing\\scripts\\process_insights.py\", line 282, in process_insights","timestamp":"2025-04-18T18:12:57.394Z"}
{"level":"error","message":"[process_insights.py Error] save_insights_to_db(all_insights)","timestamp":"2025-04-18T18:12:57.395Z"}
{"level":"error","message":"[process_insights.py Error] File \"C:\\Users\\atoda\\Documents\\Money_Mate\\data_processing\\scripts\\process_insights.py\", line 234, in save_insights_to_db\r\n    execute_values(cur, insert_query, data)\r\n  File \"C:\\Users\\atoda\\Documents\\Money_Mate\\venv\\Lib\\site-packages\\psycopg2\\extras.py\", line 1299, in execute_values","timestamp":"2025-04-18T18:12:57.395Z"}
{"level":"error","message":"[process_insights.py Error] cur.execute(b''.join(parts))\r\npsycopg2.errors.InvalidTextRepresentation: invalid input value for enum enum_financial_insights_insight_type: \"Monthly Spend Summary\"\r\nLINE 5: ...   VALUES ('99a85acc-7b40-4555-95c1-972b9fe5c3be','Monthly S...\r\n                                                             ^","timestamp":"2025-04-18T18:12:57.399Z"}
{"level":"error","message":"[process_insights.py Error] Traceback (most recent call last):\r\n  File \"C:\\Users\\atoda\\Documents\\Money_Mate\\data_processing\\scripts\\process_insights.py\", line 297, in <module>\r\n    process_insights() \r\n    ^^^^^^^^^^^^^^^^^^\r\n  File \"C:\\Users\\atoda\\Documents\\Money_Mate\\data_processing\\scripts\\process_insights.py\", line 282, in process_insights","timestamp":"2025-04-18T18:12:57.478Z"}
{"level":"error","message":"[process_insights.py Error] save_insights_to_db(all_insights)\r\n  File \"C:\\Users\\atoda\\Documents\\Money_Mate\\data_processing\\scripts\\process_insights.py\", line 234, in save_insights_to_db","timestamp":"2025-04-18T18:12:57.478Z"}
{"level":"error","message":"[process_insights.py Error] execute_values(cur, insert_query, data)\r\n  File \"C:\\Users\\atoda\\Documents\\Money_Mate\\venv\\Lib\\site-packages\\psycopg2\\extras.py\", line 1299, in execute_values","timestamp":"2025-04-18T18:12:57.479Z"}
{"level":"error","message":"[process_insights.py Error] cur.execute(b''.join(parts))","timestamp":"2025-04-18T18:12:57.479Z"}
{"level":"error","message":"[process_insights.py Error] psycopg2.errors.InvalidTextRepresentation: invalid input value for enum enum_financial_insights_insight_type: \"Monthly Spend Summary\"\r\nLINE 5: ...   VALUES ('6c1517d4-e841-46b1-91bb-cbafc2ce4436','Monthly S...\r\n                                                             ^","timestamp":"2025-04-18T18:12:57.480Z"}
{"level":"error","message":"❌ process_insights.py failed with code 1","timestamp":"2025-04-18T18:12:58.075Z"}
{"level":"error","message":"❌ process_insights.py failed with code 1","timestamp":"2025-04-18T18:12:58.227Z"}
{"constraint":"transactions_user_id_fkey","level":"error","message":"❌ Error synchronizing database: Unknown constraint error","name":"SequelizeUnknownConstraintError","original":{"code":"42704","file":"tablecmds.c","length":150,"line":"12607","name":"error","routine":"ATExecDropConstraint","severity":"ERROR","sql":"ALTER TABLE \"transactions\" DROP CONSTRAINT \"transactions_user_id_fkey\""},"parameters":{},"parent":{"code":"42704","file":"tablecmds.c","length":150,"line":"12607","name":"error","routine":"ATExecDropConstraint","severity":"ERROR","sql":"ALTER TABLE \"transactions\" DROP CONSTRAINT \"transactions_user_id_fkey\""},"sql":"ALTER TABLE \"transactions\" DROP CONSTRAINT \"transactions_user_id_fkey\"","stack":"Error\n    at Query.run (C:\\Users\\atoda\\Documents\\Money_Mate\\BackEnd\\node_modules\\sequelize\\src\\dialects\\postgres\\query.js:76:25)\n    at C:\\Users\\atoda\\Documents\\Money_Mate\\BackEnd\\node_modules\\sequelize\\src\\sequelize.js:650:28\n    at processTicksAndRejections (node:internal/process/task_queues:95:5)\n    at async Function.sync (C:\\Users\\atoda\\Documents\\Money_Mate\\BackEnd\\node_modules\\sequelize\\src\\model.js:1402:17)\n    at async Sequelize.sync (C:\\Users\\atoda\\Documents\\Money_Mate\\BackEnd\\node_modules\\sequelize\\src\\sequelize.js:825:9)","table":"transactions","timestamp":"2025-04-18T18:13:55.072Z"}
{"level":"error","message":"[process_insights.py Error] C:\\Users\\atoda\\Documents\\Money_Mate\\data_processing\\scripts\\process_insights.py:252: UserWarning: pandas only supports SQLAlchemy connectable (engine/connection) or database string URI or sqlite3 DBAPI2 connection. Other DBAPI2 objects are not tested. Please consider using SQLAlchemy.\r\n  transactions = pd.read_sql(\"SELECT * FROM transactions\", conn)","timestamp":"2025-04-18T18:13:58.936Z"}
{"level":"error","message":"[process_insights.py Error] C:\\Users\\atoda\\Documents\\Money_Mate\\data_processing\\scripts\\process_insights.py:253: UserWarning: pandas only supports SQLAlchemy connectable (engine/connection) or database string URI or sqlite3 DBAPI2 connection. Other DBAPI2 objects are not tested. Please consider using SQLAlchemy.\r\n  categories = pd.read_sql(\"SELECT * FROM categories\", conn)","timestamp":"2025-04-18T18:14:00.220Z"}
{"level":"error","message":"[process_insights.py Error] C:\\Users\\atoda\\Documents\\Money_Mate\\data_processing\\scripts\\process_insights.py:254: UserWarning: pandas only supports SQLAlchemy connectable (engine/connection) or database string URI or sqlite3 DBAPI2 connection. Other DBAPI2 objects are not tested. Please consider using SQLAlchemy.\r\n  users = pd.read_sql(\"SELECT * FROM users\", conn)","timestamp":"2025-04-18T18:14:00.573Z"}
{"level":"error","message":"[process_insights.py Error] C:\\Users\\atoda\\Documents\\Money_Mate\\data_processing\\scripts\\process_insights.py:148: UserWarning: Converting to PeriodArray/Index representation will drop timezone information.\r\n  transactions['month'] = transactions['transaction_date'].dt.to_period('M')","timestamp":"2025-04-18T18:14:00.892Z"}
{"level":"error","message":"[process_insights.py Error] C:\\Users\\atoda\\Documents\\Money_Mate\\data_processing\\scripts\\process_insights.py:92: UserWarning: Converting to PeriodArray/Index representation will drop timezone information.\r\n  transactions['month'] = transactions['transaction_date'].dt.to_period('M')","timestamp":"2025-04-18T18:14:00.924Z"}
{"level":"error","message":"[process_insights.py Error] Traceback (most recent call last):\r\n  File \"C:\\Users\\atoda\\Documents\\Money_Mate\\data_processing\\scripts\\process_insights.py\", line 297, in <module>\r\n    process_insights() \r\n    ^^^^^^^^^^^^^^^^^^\r\n  File \"C:\\Users\\atoda\\Documents\\Money_Mate\\data_processing\\scripts\\process_insights.py\", line 282, in process_insights","timestamp":"2025-04-18T18:14:03.987Z"}
{"level":"error","message":"[process_insights.py Error] save_insights_to_db(all_insights)\r\n  File \"C:\\Users\\atoda\\Documents\\Money_Mate\\data_processing\\scripts\\process_insights.py\", line 234, in save_insights_to_db\r\n    execute_values(cur, insert_query, data)\r\n  File \"C:\\Users\\atoda\\Documents\\Money_Mate\\venv\\Lib\\site-packages\\psycopg2\\extras.py\", line 1299, in execute_values","timestamp":"2025-04-18T18:14:03.988Z"}
{"level":"error","message":"[process_insights.py Error] cur.execute(b''.join(parts))","timestamp":"2025-04-18T18:14:03.988Z"}
{"level":"error","message":"[process_insights.py Error] psycopg2.errors.UndefinedTable: relation \"financial_insights\" does not exist\r\nLINE 2:                 INSERT INTO financial_insights \r\n                                    ^","timestamp":"2025-04-18T18:14:03.989Z"}
{"level":"error","message":"❌ process_insights.py failed with code 1","timestamp":"2025-04-18T18:14:04.218Z"}
{"level":"error","message":"[process_insights.py Error] C:\\Users\\atoda\\Documents\\Money_Mate\\data_processing\\scripts\\process_insights.py:252: UserWarning: pandas only supports SQLAlchemy connectable (engine/connection) or database string URI or sqlite3 DBAPI2 connection. Other DBAPI2 objects are not tested. Please consider using SQLAlchemy.\r\n  transactions = pd.read_sql(\"SELECT * FROM transactions\", conn)","timestamp":"2025-04-18T18:14:21.445Z"}
{"level":"error","message":"[process_insights.py Error] C:\\Users\\atoda\\Documents\\Money_Mate\\data_processing\\scripts\\process_insights.py:253: UserWarning: pandas only supports SQLAlchemy connectable (engine/connection) or database string URI or sqlite3 DBAPI2 connection. Other DBAPI2 objects are not tested. Please consider using SQLAlchemy.\r\n  categories = pd.read_sql(\"SELECT * FROM categories\", conn)","timestamp":"2025-04-18T18:14:22.546Z"}
{"level":"error","message":"[process_insights.py Error] C:\\Users\\atoda\\Documents\\Money_Mate\\data_processing\\scripts\\process_insights.py:254: UserWarning: pandas only supports SQLAlchemy connectable (engine/connection) or database string URI or sqlite3 DBAPI2 connection. Other DBAPI2 objects are not tested. Please consider using SQLAlchemy.\r\n  users = pd.read_sql(\"SELECT * FROM users\", conn)","timestamp":"2025-04-18T18:14:22.851Z"}
{"level":"error","message":"[process_insights.py Error] C:\\Users\\atoda\\Documents\\Money_Mate\\data_processing\\scripts\\process_insights.py:148: UserWarning: Converting to PeriodArray/Index representation will drop timezone information.\r\n  transactions['month'] = transactions['transaction_date'].dt.to_period('M')","timestamp":"2025-04-18T18:14:23.128Z"}
{"level":"error","message":"[process_insights.py Error] C:\\Users\\atoda\\Documents\\Money_Mate\\data_processing\\scripts\\process_insights.py:92: UserWarning: Converting to PeriodArray/Index representation will drop timezone information.\r\n  transactions['month'] = transactions['transaction_date'].dt.to_period('M')","timestamp":"2025-04-18T18:14:23.157Z"}
{"level":"error","message":"[process_insights.py Error] Traceback (most recent call last):\r\n  File \"C:\\Users\\atoda\\Documents\\Money_Mate\\data_processing\\scripts\\process_insights.py\", line 297, in <module>\r\n    process_insights()","timestamp":"2025-04-18T18:14:26.513Z"}
{"level":"error","message":"[process_insights.py Error] ^^^^^^^^^^^^^^^^^^\r\n  File \"C:\\Users\\atoda\\Documents\\Money_Mate\\data_processing\\scripts\\process_insights.py\", line 282, in process_insights","timestamp":"2025-04-18T18:14:26.514Z"}
{"level":"error","message":"[process_insights.py Error] save_insights_to_db(all_insights)\r\n  File \"C:\\Users\\atoda\\Documents\\Money_Mate\\data_processing\\scripts\\process_insights.py\", line 234, in save_insights_to_db","timestamp":"2025-04-18T18:14:26.514Z"}
{"level":"error","message":"[process_insights.py Error] execute_values(cur, insert_query, data)\r\n  File \"C:\\Users\\atoda\\Documents\\Money_Mate\\venv\\Lib\\site-packages\\psycopg2\\extras.py\", line 1299, in execute_values","timestamp":"2025-04-18T18:14:26.514Z"}
{"level":"error","message":"[process_insights.py Error] cur.execute(b''.join(parts))","timestamp":"2025-04-18T18:14:26.515Z"}
{"level":"error","message":"[process_insights.py Error] psycopg2.errors.NotNullViolation: null value in column \"created_at\" of relation \"financial_insights\" violates not-null constraint\r\nDETAIL:  Failing row contains (b5e152af-6459-4374-9c14-903a1a5bfbe6, Monthly Spend Summary, 2023-04, null, null, 765.97, null, null, null, null, 839a60a1-91b1-4d97-a935-5724cf3463bb, null).","timestamp":"2025-04-18T18:14:26.515Z"}
{"level":"error","message":"❌ process_insights.py failed with code 1","timestamp":"2025-04-18T18:14:26.740Z"}
{"level":"error","message":"❌ Error synchronizing database: Cannot read properties of null (reading '1')","stack":"TypeError: Cannot read properties of null (reading '1')\n    at Query.run (C:\\Users\\atoda\\Documents\\Money_Mate\\BackEnd\\node_modules\\sequelize\\src\\dialects\\postgres\\query.js:151:75)\n    at processTicksAndRejections (node:internal/process/task_queues:95:5)\n    at async C:\\Users\\atoda\\Documents\\Money_Mate\\BackEnd\\node_modules\\sequelize\\src\\sequelize.js:650:16\n    at async PostgresQueryInterface.showIndex (C:\\Users\\atoda\\Documents\\Money_Mate\\BackEnd\\node_modules\\sequelize\\src\\dialects\\abstract\\query-interface.js:600:12)\n    at async Function.sync (C:\\Users\\atoda\\Documents\\Money_Mate\\BackEnd\\node_modules\\sequelize\\src\\model.js:1413:29)\n    at async Sequelize.sync (C:\\Users\\atoda\\Documents\\Money_Mate\\BackEnd\\node_modules\\sequelize\\src\\sequelize.js:825:9)","timestamp":"2025-04-18T18:17:30.776Z"}
{"level":"error","message":"[process_insights.py Error] Traceback (most recent call last):\r\n  File \"C:\\Users\\atoda\\Documents\\Money_Mate\\data_processing\\scripts\\process_insights.py\", line 306, in <module>","timestamp":"2025-04-18T18:17:33.711Z"}
{"level":"error","message":"[process_insights.py Error] process_insights()","timestamp":"2025-04-18T18:17:33.712Z"}
{"level":"error","message":"[process_insights.py Error] ^^^^^^^^^^^^^^^^^^\r\n  File \"C:\\Users\\atoda\\Documents\\Money_Mate\\data_processing\\scripts\\process_insights.py\", line 254, in process_insights","timestamp":"2025-04-18T18:17:33.712Z"}
{"level":"error","message":"[process_insights.py Error] engine = get_db_engine()","timestamp":"2025-04-18T18:17:33.713Z"}
{"level":"error","message":"[process_insights.py Error] ^^^^^^^^^^^^^^^\r\n  File \"C:\\Users\\atoda\\Documents\\Money_Mate\\data_processing\\scripts\\process_insights.py\", line 23, in get_db_engine\r\n    return create_engine(f'postgresql://{DB_USER}:{DB_PASS}@{DB_HOST}:{DB_PORT}/{DB_NAME}')","timestamp":"2025-04-18T18:17:33.713Z"}
{"level":"error","message":"[process_insights.py Error] ^^^^^^^^^^^^^^^^^^^^^^^^^^^^^^^^^^^^^^^^^^^^^^^^^^^^^^^^^^^^^^^^^^^^^^^^^^^^^^^^\r\n  File \"<string>\", line 2, in create_engine\r\n  File \"C:\\Users\\atoda\\Documents\\Money_Mate\\venv\\Lib\\site-packages\\sqlalchemy\\util\\deprecations.py\", line 281, in warned","timestamp":"2025-04-18T18:17:33.713Z"}
{"level":"error","message":"[process_insights.py Error] return fn(*args, **kwargs)  # type: ignore[no-any-return]","timestamp":"2025-04-18T18:17:33.714Z"}
{"level":"error","message":"[process_insights.py Error] ^^^^^^^^^^^^^^^^^^^\r\n  File \"C:\\Users\\atoda\\Documents\\Money_Mate\\venv\\Lib\\site-packages\\sqlalchemy\\engine\\create.py\", line 549, in create_engine","timestamp":"2025-04-18T18:17:33.715Z"}
{"level":"error","message":"[process_insights.py Error] u = _url.make_url(url)","timestamp":"2025-04-18T18:17:33.716Z"}
{"level":"error","message":"[process_insights.py Error] ^^^^^^^^^^^^^^^^^^\r\n  File \"C:\\Users\\atoda\\Documents\\Money_Mate\\venv\\Lib\\site-packages\\sqlalchemy\\engine\\url.py\", line 856, in make_url","timestamp":"2025-04-18T18:17:33.716Z"}
{"level":"error","message":"[process_insights.py Error] return _parse_url(name_or_url)","timestamp":"2025-04-18T18:17:33.717Z"}
{"level":"error","message":"[process_insights.py Error] ^^^^^^^^^^^^^^^^^^^^^^^\r\n  File \"C:\\Users\\atoda\\Documents\\Money_Mate\\venv\\Lib\\site-packages\\sqlalchemy\\engine\\url.py\", line 917, in _parse_url","timestamp":"2025-04-18T18:17:33.718Z"}
{"level":"error","message":"[process_insights.py Error] components[\"port\"] = int(components[\"port\"])\r\n                         ^^^^^^^^^^^^^^^^^^^^^^^\r\nValueError: invalid literal for int() with base 10: 'None'","timestamp":"2025-04-18T18:17:33.718Z"}
{"level":"error","message":"❌ process_insights.py failed with code 1","timestamp":"2025-04-18T18:17:34.084Z"}
{"level":"error","message":"[process_insights.py Error] Traceback (most recent call last):\r\n  File \"C:\\Users\\atoda\\Documents\\Money_Mate\\data_processing\\scripts\\process_insights.py\", line 306, in <module>\r\n    process_insights() \r\n    ^^^^^^^^^^^^^^^^^^\r\n  File \"C:\\Users\\atoda\\Documents\\Money_Mate\\data_processing\\scripts\\process_insights.py\", line 254, in process_insights","timestamp":"2025-04-18T18:18:05.668Z"}
{"level":"error","message":"[process_insights.py Error] engine = get_db_engine()\r\n             ^^^^^^^^^^^^^^^\r\n  File \"C:\\Users\\atoda\\Documents\\Money_Mate\\data_processing\\scripts\\process_insights.py\", line 23, in get_db_engine\r\n    return create_engine(f'postgresql://{DB_USER}:{DB_PASS}@{DB_HOST}:{DB_PORT}/{DB_NAME}')\r\n           ^^^^^^^^^^^^^^^^^^^^^^^^^^^^^^^^^^^^^^^^^^^^^^^^^^^^^^^^^^^^^^^^^^^^^^^^^^^^^^^^","timestamp":"2025-04-18T18:18:05.669Z"}
{"level":"error","message":"[process_insights.py Error] File \"<string>\", line 2, in create_engine\r\n  File \"C:\\Users\\atoda\\Documents\\Money_Mate\\venv\\Lib\\site-packages\\sqlalchemy\\util\\deprecations.py\", line 281, in warned","timestamp":"2025-04-18T18:18:05.669Z"}
{"level":"error","message":"[process_insights.py Error] return fn(*args, **kwargs)  # type: ignore[no-any-return]\r\n           ^^^^^^^^^^^^^^^^^^^\r\n  File \"C:\\Users\\atoda\\Documents\\Money_Mate\\venv\\Lib\\site-packages\\sqlalchemy\\engine\\create.py\", line 549, in create_engine","timestamp":"2025-04-18T18:18:05.669Z"}
{"level":"error","message":"[process_insights.py Error] u = _url.make_url(url)","timestamp":"2025-04-18T18:18:05.669Z"}
{"level":"error","message":"[process_insights.py Error] ^^^^^^^^^^^^^^^^^^\r\n  File \"C:\\Users\\atoda\\Documents\\Money_Mate\\venv\\Lib\\site-packages\\sqlalchemy\\engine\\url.py\", line 856, in make_url","timestamp":"2025-04-18T18:18:05.670Z"}
{"level":"error","message":"[process_insights.py Error] return _parse_url(name_or_url)\r\n           ^^^^^^^^^^^^^^^^^^^^^^^\r\n  File \"C:\\Users\\atoda\\Documents\\Money_Mate\\venv\\Lib\\site-packages\\sqlalchemy\\engine\\url.py\", line 917, in _parse_url","timestamp":"2025-04-18T18:18:05.670Z"}
{"level":"error","message":"[process_insights.py Error] components[\"port\"] = int(components[\"port\"])","timestamp":"2025-04-18T18:18:05.670Z"}
{"level":"error","message":"[process_insights.py Error] ^^^^^^^^^^^^^^^^^^^^^^^\r\nValueError: invalid literal for int() with base 10: 'None'","timestamp":"2025-04-18T18:18:05.671Z"}
{"level":"error","message":"❌ process_insights.py failed with code 1","timestamp":"2025-04-18T18:18:05.941Z"}
{"constraint":"messages_user_id_fkey","level":"error","message":"❌ Error synchronizing database: Unknown constraint error","name":"SequelizeUnknownConstraintError","original":{"code":"42704","file":"tablecmds.c","length":142,"line":"12607","name":"error","routine":"ATExecDropConstraint","severity":"ERROR","sql":"ALTER TABLE \"messages\" DROP CONSTRAINT \"messages_user_id_fkey\""},"parameters":{},"parent":{"code":"42704","file":"tablecmds.c","length":142,"line":"12607","name":"error","routine":"ATExecDropConstraint","severity":"ERROR","sql":"ALTER TABLE \"messages\" DROP CONSTRAINT \"messages_user_id_fkey\""},"sql":"ALTER TABLE \"messages\" DROP CONSTRAINT \"messages_user_id_fkey\"","stack":"Error\n    at Query.run (C:\\Users\\atoda\\Documents\\Money_Mate\\BackEnd\\node_modules\\sequelize\\src\\dialects\\postgres\\query.js:76:25)\n    at C:\\Users\\atoda\\Documents\\Money_Mate\\BackEnd\\node_modules\\sequelize\\src\\sequelize.js:650:28\n    at processTicksAndRejections (node:internal/process/task_queues:95:5)\n    at async Function.sync (C:\\Users\\atoda\\Documents\\Money_Mate\\BackEnd\\node_modules\\sequelize\\src\\model.js:1402:17)\n    at async Sequelize.sync (C:\\Users\\atoda\\Documents\\Money_Mate\\BackEnd\\node_modules\\sequelize\\src\\sequelize.js:825:9)","table":"messages","timestamp":"2025-04-18T18:21:55.892Z"}
{"level":"error","message":"[process_insights.py Error] Traceback (most recent call last):\r\n  File \"C:\\Users\\atoda\\Documents\\Money_Mate\\data_processing\\scripts\\process_insights.py\", line 306, in <module>\r\n    process_insights() \r\n    ^^^^^^^^^^^^^^^^^^\r\n  File \"C:\\Users\\atoda\\Documents\\Money_Mate\\data_processing\\scripts\\process_insights.py\", line 291, in process_insights\r\n    save_insights_to_db(all_insights)\r\n  File \"C:\\Users\\atoda\\Documents\\Money_Mate\\data_processing\\scripts\\process_insights.py\", line 239, in save_insights_to_db","timestamp":"2025-04-18T18:22:12.994Z"}
{"level":"error","message":"[process_insights.py Error] execute_values(cur, insert_query, data)\r\n    ^^^^^^^^^^^^^^","timestamp":"2025-04-18T18:22:12.995Z"}
{"level":"error","message":"[process_insights.py Error] NameError: name 'execute_values' is not defined","timestamp":"2025-04-18T18:22:12.995Z"}
{"level":"error","message":"❌ process_insights.py failed with code 1","timestamp":"2025-04-18T18:22:13.259Z"}
{"level":"error","message":"[process_insights.py Error] Traceback (most recent call last):\r\n  File \"C:\\Users\\atoda\\Documents\\Money_Mate\\data_processing\\scripts\\process_insights.py\", line 306, in <module>\r\n    process_insights() \r\n    ^^^^^^^^^^^^^^^^^^\r\n  File \"C:\\Users\\atoda\\Documents\\Money_Mate\\data_processing\\scripts\\process_insights.py\", line 291, in process_insights","timestamp":"2025-04-18T18:22:46.064Z"}
{"level":"error","message":"[process_insights.py Error] save_insights_to_db(all_insights)\r\n  File \"C:\\Users\\atoda\\Documents\\Money_Mate\\data_processing\\scripts\\process_insights.py\", line 239, in save_insights_to_db\r\n    execute_values(cur, insert_query, data)\r\n    ^^^^^^^^^^^^^^\r\nNameError: name 'execute_values' is not defined","timestamp":"2025-04-18T18:22:46.064Z"}
{"level":"error","message":"❌ process_insights.py failed with code 1","timestamp":"2025-04-18T18:22:46.391Z"}
{"constraint":"transactions_user_id_fkey","level":"error","message":"❌ Error synchronizing database: Unknown constraint error","name":"SequelizeUnknownConstraintError","original":{"code":"42704","file":"tablecmds.c","length":150,"line":"12607","name":"error","routine":"ATExecDropConstraint","severity":"ERROR","sql":"ALTER TABLE \"transactions\" DROP CONSTRAINT \"transactions_user_id_fkey\""},"parameters":{},"parent":{"code":"42704","file":"tablecmds.c","length":150,"line":"12607","name":"error","routine":"ATExecDropConstraint","severity":"ERROR","sql":"ALTER TABLE \"transactions\" DROP CONSTRAINT \"transactions_user_id_fkey\""},"sql":"ALTER TABLE \"transactions\" DROP CONSTRAINT \"transactions_user_id_fkey\"","stack":"Error\n    at Query.run (C:\\Users\\atoda\\Documents\\Money_Mate\\BackEnd\\node_modules\\sequelize\\src\\dialects\\postgres\\query.js:76:25)\n    at C:\\Users\\atoda\\Documents\\Money_Mate\\BackEnd\\node_modules\\sequelize\\src\\sequelize.js:650:28\n    at processTicksAndRejections (node:internal/process/task_queues:95:5)\n    at async Function.sync (C:\\Users\\atoda\\Documents\\Money_Mate\\BackEnd\\node_modules\\sequelize\\src\\model.js:1402:17)\n    at async Sequelize.sync (C:\\Users\\atoda\\Documents\\Money_Mate\\BackEnd\\node_modules\\sequelize\\src\\sequelize.js:825:9)","table":"transactions","timestamp":"2025-04-18T18:28:08.174Z"}
{"level":"error","message":"[process_insights.py Error] Traceback (most recent call last):\r\n  File \"C:\\Users\\atoda\\Documents\\Money_Mate\\data_processing\\scripts\\process_insights.py\", line 302, in <module>","timestamp":"2025-04-18T18:28:23.719Z"}
{"level":"error","message":"[process_insights.py Error] process_insights() \r\n    ^^^^^^^^^^^^^^^^^^\r\n  File \"C:\\Users\\atoda\\Documents\\Money_Mate\\data_processing\\scripts\\process_insights.py\", line 287, in process_insights","timestamp":"2025-04-18T18:28:23.720Z"}
{"level":"error","message":"[process_insights.py Error] save_insights_to_db(all_insights)\r\n  File \"C:\\Users\\atoda\\Documents\\Money_Mate\\data_processing\\scripts\\process_insights.py\", line 235, in save_insights_to_db","timestamp":"2025-04-18T18:28:23.721Z"}
{"level":"error","message":"[process_insights.py Error] execute_values(cur, insert_query, data)\r\n  File \"C:\\Users\\atoda\\Documents\\Money_Mate\\venv\\Lib\\site-packages\\psycopg2\\extras.py\", line 1299, in execute_values","timestamp":"2025-04-18T18:28:23.721Z"}
{"level":"error","message":"[process_insights.py Error] cur.execute(b''.join(parts))","timestamp":"2025-04-18T18:28:23.723Z"}
{"level":"error","message":"[process_insights.py Error] psycopg2.errors.NotNullViolation: null value in column \"created_at\" of relation \"financial_insights\" violates not-null constraint\r\nDETAIL:  Failing row contains (8a6fa418-2373-470a-8de4-797a82819e78, Monthly Spend Summary, 2023-04, null, null, 765.97, null, null, null, null, 839a60a1-91b1-4d97-a935-5724cf3463bb, null).","timestamp":"2025-04-18T18:28:23.724Z"}
{"level":"error","message":"❌ process_insights.py failed with code 1","timestamp":"2025-04-18T18:28:24.043Z"}
{"level":"error","message":"[process_insights.py Error] Traceback (most recent call last):\r\n  File \"C:\\Users\\atoda\\Documents\\Money_Mate\\data_processing\\scripts\\process_insights.py\", line 302, in <module>\r\n    process_insights() \r\n    ^^^^^^^^^^^^^^^^^^\r\n  File \"C:\\Users\\atoda\\Documents\\Money_Mate\\data_processing\\scripts\\process_insights.py\", line 287, in process_insights\r\n    save_insights_to_db(all_insights)\r\n  File \"C:\\Users\\atoda\\Documents\\Money_Mate\\data_processing\\scripts\\process_insights.py\", line 235, in save_insights_to_db","timestamp":"2025-04-18T18:28:53.959Z"}
{"level":"error","message":"[process_insights.py Error] execute_values(cur, insert_query, data)\r\n  File \"C:\\Users\\atoda\\Documents\\Money_Mate\\venv\\Lib\\site-packages\\psycopg2\\extras.py\", line 1299, in execute_values","timestamp":"2025-04-18T18:28:53.965Z"}
{"level":"error","message":"[process_insights.py Error] cur.execute(b''.join(parts))\r\npsycopg2.errors.NotNullViolation: null value in column \"createdAt\" of relation \"financial_insights\" violates not-null constraint\r\nDETAIL:  Failing row contains (2ad70bf0-2391-416d-be71-ad81dc2cb633, Monthly Spend Summary, 2023-04, null, null, 765.97, null, null, null, null, 839a60a1-91b1-4d97-a935-5724cf3463bb, null, null).","timestamp":"2025-04-18T18:28:53.970Z"}
{"level":"error","message":"❌ process_insights.py failed with code 1","timestamp":"2025-04-18T18:28:54.885Z"}
{"level":"error","message":"❌ Server startup failed: Connection terminated unexpectedly","name":"SequelizeConnectionError","original":{},"parent":{},"stack":"SequelizeConnectionError: Connection terminated unexpectedly\n    at Client._connectionCallback (C:\\Users\\atoda\\Documents\\Money_Mate\\BackEnd\\node_modules\\sequelize\\src\\dialects\\postgres\\connection-manager.js:200:20)\n    at Connection.<anonymous> (C:\\Users\\atoda\\Documents\\Money_Mate\\BackEnd\\node_modules\\pg\\lib\\client.js:149:18)\n    at Object.onceWrapper (node:events:632:28)\n    at Connection.emit (node:events:518:28)\n    at Connection.emit (node:domain:488:12)\n    at Socket.<anonymous> (C:\\Users\\atoda\\Documents\\Money_Mate\\BackEnd\\node_modules\\pg\\lib\\connection.js:62:12)\n    at Socket.emit (node:events:530:35)\n    at Socket.emit (node:domain:488:12)\n    at TCP.<anonymous> (node:net:337:12)","timestamp":"2025-04-18T18:32:22.405Z"}
{"level":"error","message":"❌ Server startup failed: Connection terminated unexpectedly","name":"SequelizeConnectionError","original":{},"parent":{},"stack":"SequelizeConnectionError: Connection terminated unexpectedly\n    at Client._connectionCallback (C:\\Users\\atoda\\Documents\\Money_Mate\\BackEnd\\node_modules\\sequelize\\src\\dialects\\postgres\\connection-manager.js:200:20)\n    at Connection.<anonymous> (C:\\Users\\atoda\\Documents\\Money_Mate\\BackEnd\\node_modules\\pg\\lib\\client.js:149:18)\n    at Object.onceWrapper (node:events:632:28)\n    at Connection.emit (node:events:518:28)\n    at Connection.emit (node:domain:488:12)\n    at Socket.<anonymous> (C:\\Users\\atoda\\Documents\\Money_Mate\\BackEnd\\node_modules\\pg\\lib\\connection.js:62:12)\n    at Socket.emit (node:events:530:35)\n    at Socket.emit (node:domain:488:12)\n    at TCP.<anonymous> (node:net:337:12)","timestamp":"2025-04-18T18:32:24.426Z"}
{"level":"error","message":"[process_insights.py Error] Traceback (most recent call last):\r\n  File \"C:\\Users\\atoda\\Documents\\Money_Mate\\data_processing\\scripts\\process_insights.py\", line 302, in <module>\r\n    process_insights() \r\n    ^^^^^^^^^^^^^^^^^^\r\n  File \"C:\\Users\\atoda\\Documents\\Money_Mate\\data_processing\\scripts\\process_insights.py\", line 287, in process_insights\r\n    save_insights_to_db(all_insights)\r\n  File \"C:\\Users\\atoda\\Documents\\Money_Mate\\data_processing\\scripts\\process_insights.py\", line 235, in save_insights_to_db\r\n    execute_values(cur, insert_query, data)\r\n  File \"C:\\Users\\atoda\\Documents\\Money_Mate\\venv\\Lib\\site-packages\\psycopg2\\extras.py\", line 1299, in execute_values","timestamp":"2025-04-18T18:33:47.278Z"}
{"level":"error","message":"[process_insights.py Error] cur.execute(b''.join(parts))\r\npsycopg2.errors.NotNullViolation: null value in column \"createdAt\" of relation \"financial_insights\" violates not-null constraint\r\nDETAIL:  Failing row contains (86224286-74de-4a0c-9b3d-89f367469a04, Monthly Spend Summary, 2023-04, null, null, 765.97, null, null, null, null, 839a60a1-91b1-4d97-a935-5724cf3463bb, null, null).","timestamp":"2025-04-18T18:33:47.279Z"}
{"level":"error","message":"❌ process_insights.py failed with code 1","timestamp":"2025-04-18T18:33:47.612Z"}
{"constraint":"messages_user_id_fkey","level":"error","message":"❌ Error synchronizing database: Unknown constraint error","name":"SequelizeUnknownConstraintError","original":{"code":"42704","file":"tablecmds.c","length":142,"line":"12607","name":"error","routine":"ATExecDropConstraint","severity":"ERROR","sql":"ALTER TABLE \"messages\" DROP CONSTRAINT \"messages_user_id_fkey\""},"parameters":{},"parent":{"code":"42704","file":"tablecmds.c","length":142,"line":"12607","name":"error","routine":"ATExecDropConstraint","severity":"ERROR","sql":"ALTER TABLE \"messages\" DROP CONSTRAINT \"messages_user_id_fkey\""},"sql":"ALTER TABLE \"messages\" DROP CONSTRAINT \"messages_user_id_fkey\"","stack":"Error\n    at Query.run (C:\\Users\\atoda\\Documents\\Money_Mate\\BackEnd\\node_modules\\sequelize\\src\\dialects\\postgres\\query.js:76:25)\n    at C:\\Users\\atoda\\Documents\\Money_Mate\\BackEnd\\node_modules\\sequelize\\src\\sequelize.js:650:28\n    at processTicksAndRejections (node:internal/process/task_queues:95:5)\n    at async Function.sync (C:\\Users\\atoda\\Documents\\Money_Mate\\BackEnd\\node_modules\\sequelize\\src\\model.js:1402:17)\n    at async Sequelize.sync (C:\\Users\\atoda\\Documents\\Money_Mate\\BackEnd\\node_modules\\sequelize\\src\\sequelize.js:825:9)","table":"messages","timestamp":"2025-04-18T18:39:43.917Z"}
{"level":"error","message":"❌ Error synchronizing database: column \"createdAt\" of relation \"financial_insights\" contains null values","name":"SequelizeDatabaseError","original":{"code":"23502","column":"createdAt","file":"tablecmds.c","length":174,"line":"6279","name":"error","routine":"ATRewriteTable","schema":"public","severity":"ERROR","sql":"ALTER TABLE \"public\".\"financial_insights\" ADD COLUMN \"createdAt\" TIMESTAMP WITH TIME ZONE NOT NULL;","table":"financial_insights"},"parameters":{},"parent":{"code":"23502","column":"createdAt","file":"tablecmds.c","length":174,"line":"6279","name":"error","routine":"ATRewriteTable","schema":"public","severity":"ERROR","sql":"ALTER TABLE \"public\".\"financial_insights\" ADD COLUMN \"createdAt\" TIMESTAMP WITH TIME ZONE NOT NULL;","table":"financial_insights"},"sql":"ALTER TABLE \"public\".\"financial_insights\" ADD COLUMN \"createdAt\" TIMESTAMP WITH TIME ZONE NOT NULL;","stack":"Error\n    at Query.run (C:\\Users\\atoda\\Documents\\Money_Mate\\BackEnd\\node_modules\\sequelize\\src\\dialects\\postgres\\query.js:76:25)\n    at C:\\Users\\atoda\\Documents\\Money_Mate\\BackEnd\\node_modules\\sequelize\\src\\sequelize.js:650:28\n    at processTicksAndRejections (node:internal/process/task_queues:95:5)\n    at async PostgresQueryInterface.addColumn (C:\\Users\\atoda\\Documents\\Money_Mate\\BackEnd\\node_modules\\sequelize\\src\\dialects\\abstract\\query-interface.js:430:12)\n    at async Function.sync (C:\\Users\\atoda\\Documents\\Money_Mate\\BackEnd\\node_modules\\sequelize\\src\\model.js:1373:11)\n    at async Sequelize.sync (C:\\Users\\atoda\\Documents\\Money_Mate\\BackEnd\\node_modules\\sequelize\\src\\sequelize.js:825:9)","timestamp":"2025-04-18T18:40:04.951Z"}
{"level":"error","message":"❌ Server startup failed: connect EACCES 52.167.188.143:5432","name":"SequelizeConnectionError","original":{"address":"52.167.188.143","code":"EACCES","errno":-4092,"port":5432,"syscall":"connect"},"parent":{"address":"52.167.188.143","code":"EACCES","errno":-4092,"port":5432,"syscall":"connect"},"stack":"SequelizeConnectionError: connect EACCES 52.167.188.143:5432\n    at Client._connectionCallback (C:\\Users\\atoda\\Documents\\Money_Mate\\BackEnd\\node_modules\\sequelize\\src\\dialects\\postgres\\connection-manager.js:196:24)\n    at Client._handleErrorWhileConnecting (C:\\Users\\atoda\\Documents\\Money_Mate\\BackEnd\\node_modules\\pg\\lib\\client.js:336:19)\n    at Client._handleErrorEvent (C:\\Users\\atoda\\Documents\\Money_Mate\\BackEnd\\node_modules\\pg\\lib\\client.js:346:19)\n    at Connection.emit (node:events:518:28)\n    at Connection.emit (node:domain:488:12)\n    at Socket.reportStreamError (C:\\Users\\atoda\\Documents\\Money_Mate\\BackEnd\\node_modules\\pg\\lib\\connection.js:57:12)\n    at Socket.emit (node:events:518:28)\n    at Socket.emit (node:domain:488:12)\n    at emitErrorNT (node:internal/streams/destroy:169:8)\n    at emitErrorCloseNT (node:internal/streams/destroy:128:3)","timestamp":"2025-04-19T02:08:53.815Z"}
{"level":"error","message":"❌ Server startup failed: connect EACCES 52.167.188.143:5432","name":"SequelizeConnectionError","original":{"address":"52.167.188.143","code":"EACCES","errno":-4092,"port":5432,"syscall":"connect"},"parent":{"address":"52.167.188.143","code":"EACCES","errno":-4092,"port":5432,"syscall":"connect"},"stack":"SequelizeConnectionError: connect EACCES 52.167.188.143:5432\n    at Client._connectionCallback (C:\\Users\\atoda\\Documents\\Money_Mate\\BackEnd\\node_modules\\sequelize\\src\\dialects\\postgres\\connection-manager.js:196:24)\n    at Client._handleErrorWhileConnecting (C:\\Users\\atoda\\Documents\\Money_Mate\\BackEnd\\node_modules\\pg\\lib\\client.js:336:19)\n    at Client._handleErrorEvent (C:\\Users\\atoda\\Documents\\Money_Mate\\BackEnd\\node_modules\\pg\\lib\\client.js:346:19)\n    at Connection.emit (node:events:518:28)\n    at Connection.emit (node:domain:488:12)\n    at Socket.reportStreamError (C:\\Users\\atoda\\Documents\\Money_Mate\\BackEnd\\node_modules\\pg\\lib\\connection.js:57:12)\n    at Socket.emit (node:events:518:28)\n    at Socket.emit (node:domain:488:12)\n    at emitErrorNT (node:internal/streams/destroy:169:8)\n    at emitErrorCloseNT (node:internal/streams/destroy:128:3)","timestamp":"2025-04-19T02:09:23.439Z"}
{"level":"error","message":"❌ Server startup failed: connect EACCES 52.167.188.143:5432","name":"SequelizeConnectionError","original":{"address":"52.167.188.143","code":"EACCES","errno":-4092,"port":5432,"syscall":"connect"},"parent":{"address":"52.167.188.143","code":"EACCES","errno":-4092,"port":5432,"syscall":"connect"},"stack":"SequelizeConnectionError: connect EACCES 52.167.188.143:5432\n    at Client._connectionCallback (C:\\Users\\atoda\\Documents\\Money_Mate\\BackEnd\\node_modules\\sequelize\\src\\dialects\\postgres\\connection-manager.js:196:24)\n    at Client._handleErrorWhileConnecting (C:\\Users\\atoda\\Documents\\Money_Mate\\BackEnd\\node_modules\\pg\\lib\\client.js:336:19)\n    at Client._handleErrorEvent (C:\\Users\\atoda\\Documents\\Money_Mate\\BackEnd\\node_modules\\pg\\lib\\client.js:346:19)\n    at Connection.emit (node:events:518:28)\n    at Connection.emit (node:domain:488:12)\n    at Socket.reportStreamError (C:\\Users\\atoda\\Documents\\Money_Mate\\BackEnd\\node_modules\\pg\\lib\\connection.js:57:12)\n    at Socket.emit (node:events:518:28)\n    at Socket.emit (node:domain:488:12)\n    at emitErrorNT (node:internal/streams/destroy:169:8)\n    at emitErrorCloseNT (node:internal/streams/destroy:128:3)","timestamp":"2025-04-19T02:09:43.235Z"}
{"level":"error","message":"[C:\\Users\\atoda\\Documents\\Money_Mate\\BackEnd\\final_vm.py Error] Traceback (most recent call last):\r\n  File \"C:\\Users\\atoda\\Documents\\Money_Mate\\BackEnd\\final_vm.py\", line 6, in <module>","timestamp":"2025-04-19T02:10:23.820Z"}
{"level":"error","message":"[C:\\Users\\atoda\\Documents\\Money_Mate\\BackEnd\\final_vm.py Error] import fasttext","timestamp":"2025-04-19T02:10:23.821Z"}
{"level":"error","message":"[C:\\Users\\atoda\\Documents\\Money_Mate\\BackEnd\\final_vm.py Error] ModuleNotFoundError: No module named 'fasttext'","timestamp":"2025-04-19T02:10:23.822Z"}
{"level":"error","message":"❌ C:\\Users\\atoda\\Documents\\Money_Mate\\BackEnd\\final_vm.py failed with code 1","timestamp":"2025-04-19T02:10:23.844Z"}
{"level":"error","message":"❌ Error running data processing scripts: C:\\Users\\atoda\\Documents\\Money_Mate\\BackEnd\\final_vm.py failed with code 1","stack":"Error: C:\\Users\\atoda\\Documents\\Money_Mate\\BackEnd\\final_vm.py failed with code 1\n    at ChildProcess.<anonymous> (C:\\Users\\atoda\\Documents\\Money_Mate\\BackEnd\\server.ts:61:23)\n    at ChildProcess.emit (node:events:518:28)\n    at ChildProcess.emit (node:domain:488:12)\n    at maybeClose (node:internal/child_process:1105:16)\n    at Process.ChildProcess._handle.onexit (node:internal/child_process:305:5)","timestamp":"2025-04-19T02:10:23.850Z"}
{"level":"error","timestamp":"2025-04-19T02:10:23.851Z"}
{"level":"error","message":"[pip Error] ","timestamp":"2025-04-19T02:13:26.130Z"}
{"level":"error","message":"[pip Error] error: subprocess-exited-with-error\r\n  \r\n  Getting requirements to build wheel did not run successfully.\r\n  exit code: 1\r\n  \r\n  [28 lines of output]\r\n  C:\\Users\\atoda\\Documents\\Money_Mate\\venv\\Scripts\\python.exe: No module named pip\r\n  Traceback (most recent call last):\r\n    File \"<string>\", line 38, in __init__\r\n  ModuleNotFoundError: No module named 'pybind11'\r\n  \r\n  During handling of the above exception, another exception occurred:\r\n  \r\n  Traceback (most recent call last):\r\n    File \"C:\\Users\\atoda\\Documents\\Money_Mate\\venv\\Lib\\site-packages\\pip\\_vendor\\pyproject_hooks\\_in_process\\_in_process.py\", line 353, in <module>\r\n      main()\r\n    File \"C:\\Users\\atoda\\Documents\\Money_Mate\\venv\\Lib\\site-packages\\pip\\_vendor\\pyproject_hooks\\_in_process\\_in_process.py\", line 335, in main\r\n      json_out['return_val'] = hook(**hook_input['kwargs'])\r\n                               ^^^^^^^^^^^^^^^^^^^^^^^^^^^^\r\n    File \"C:\\Users\\atoda\\Documents\\Money_Mate\\venv\\Lib\\site-packages\\pip\\_vendor\\pyproject_hooks\\_in_process\\_in_process.py\", line 118, in get_requires_for_build_wheel\r\n      return hook(config_settings)\r\n             ^^^^^^^^^^^^^^^^^^^^^\r\n    File \"C:\\Users\\atoda\\AppData\\Local\\Temp\\pip-build-env-lu2rn7xz\\overlay\\Lib\\site-packages\\setuptools\\build_meta.py\", line 334, in get_requires_for_build_wheel\r\n      return self._get_build_requires(config_settings, requirements=[])\r\n             ^^^^^^^^^^^^^^^^^^^^^^^^^^^^^^^^^^^^^^^^^^^^^^^^^^^^^^^^^^\r\n    File \"C:\\Users\\atoda\\AppData\\Local\\Temp\\pip-build-env-lu2rn7xz\\overlay\\Lib\\site-packages\\setuptools\\build_meta.py\", line 304, in _get_build_requires\r\n      self.run_setup()\r\n    File \"C:\\Users\\atoda\\AppData\\Local\\Temp\\pip-build-env-lu2rn7xz\\overlay\\Lib\\site-packages\\setuptools\\build_meta.py\", line 522, in run_setup\r\n      super().run_setup(setup_script=setup_script)\r\n    File \"C:\\Users\\atoda\\AppData\\Local\\Temp\\pip-build-env-lu2rn7xz\\overlay\\Lib\\site-packages\\setuptools\\build_meta.py\", line 320, in run_setup\r\n      exec(code, locals())\r\n    File \"<string>\", line 72, in <module>\r\n    File \"<string>\", line 41, in __init__\r\n  RuntimeError: pybind11 install failed.\r\n  [end of output]\r\n  \r\n  note: This error originates from a subprocess, and is likely not a problem with pip.","timestamp":"2025-04-19T02:13:26.130Z"}
{"level":"error","message":"[pip Error] error: subprocess-exited-with-error","timestamp":"2025-04-19T02:13:26.132Z"}
{"level":"error","message":"[pip Error] Getting requirements to build wheel did not run successfully.\r\nexit code: 1\r\n\r\nSee above for output.\r\n\r\nnote: This error originates from a subprocess, and is likely not a problem with pip.","timestamp":"2025-04-19T02:13:26.132Z"}
{"level":"error","message":"[pip Error] [notice] A new release of pip is available:","timestamp":"2025-04-19T02:13:26.207Z"}
{"level":"error","message":"[pip Error] 24.0 -> 25.0.1\r\n[notice] To update, run: python.exe -m pip install --upgrade pip","timestamp":"2025-04-19T02:13:26.208Z"}
{"level":"error","message":"❌ Failed to install Python dependencies","timestamp":"2025-04-19T02:13:26.462Z"}
{"level":"error","message":"❌ Error running data processing scripts: Failed to install Python dependencies (code 1)","stack":"Error: Failed to install Python dependencies (code 1)\n    at ChildProcess.<anonymous> (C:\\Users\\atoda\\Documents\\Money_Mate\\BackEnd\\server.ts:92:23)\n    at ChildProcess.emit (node:events:518:28)\n    at ChildProcess.emit (node:domain:488:12)\n    at maybeClose (node:internal/child_process:1105:16)\n    at Process.ChildProcess._handle.onexit (node:internal/child_process:305:5)","timestamp":"2025-04-19T02:13:26.467Z"}
{"level":"error","timestamp":"2025-04-19T02:13:26.467Z"}
{"level":"error","message":"❌ C:\\Users\\atoda\\Documents\\Money_Mate\\BackEnd\\final_vm.py failed with code 1","timestamp":"2025-04-19T02:16:07.918Z"}
{"level":"error","message":"❌ Error running data processing scripts: C:\\Users\\atoda\\Documents\\Money_Mate\\BackEnd\\final_vm.py failed with code 1","stack":"Error: C:\\Users\\atoda\\Documents\\Money_Mate\\BackEnd\\final_vm.py failed with code 1\n    at ChildProcess.<anonymous> (C:\\Users\\atoda\\Documents\\Money_Mate\\BackEnd\\server.ts:61:23)\n    at ChildProcess.emit (node:events:518:28)\n    at ChildProcess.emit (node:domain:488:12)\n    at maybeClose (node:internal/child_process:1105:16)\n    at Process.ChildProcess._handle.onexit (node:internal/child_process:305:5)","timestamp":"2025-04-19T02:16:07.928Z"}
{"level":"error","timestamp":"2025-04-19T02:16:07.928Z"}
{"level":"error","message":"❌ C:\\Users\\atoda\\Documents\\Money_Mate\\BackEnd\\final_vm.py failed with code 1","timestamp":"2025-04-19T02:43:41.008Z"}
{"level":"error","message":"❌ Error running data processing scripts: C:\\Users\\atoda\\Documents\\Money_Mate\\BackEnd\\final_vm.py failed with code 1","stack":"Error: C:\\Users\\atoda\\Documents\\Money_Mate\\BackEnd\\final_vm.py failed with code 1\n    at ChildProcess.<anonymous> (C:\\Users\\atoda\\Documents\\Money_Mate\\BackEnd\\server.ts:61:23)\n    at ChildProcess.emit (node:events:518:28)\n    at ChildProcess.emit (node:domain:488:12)\n    at maybeClose (node:internal/child_process:1105:16)\n    at Process.ChildProcess._handle.onexit (node:internal/child_process:305:5)","timestamp":"2025-04-19T02:43:41.025Z"}
{"level":"error","timestamp":"2025-04-19T02:43:41.026Z"}
{"level":"error","message":"❌ C:\\Users\\atoda\\Documents\\Money_Mate\\BackEnd\\final_vm.py failed with code 1","timestamp":"2025-04-19T02:48:39.817Z"}
{"level":"error","message":"❌ Error running data processing scripts: C:\\Users\\atoda\\Documents\\Money_Mate\\BackEnd\\final_vm.py failed with code 1","stack":"Error: C:\\Users\\atoda\\Documents\\Money_Mate\\BackEnd\\final_vm.py failed with code 1\n    at ChildProcess.<anonymous> (C:\\Users\\atoda\\Documents\\Money_Mate\\BackEnd\\server.ts:61:23)\n    at ChildProcess.emit (node:events:518:28)\n    at ChildProcess.emit (node:domain:488:12)\n    at maybeClose (node:internal/child_process:1105:16)\n    at Process.ChildProcess._handle.onexit (node:internal/child_process:305:5)","timestamp":"2025-04-19T02:48:39.818Z"}
{"level":"error","timestamp":"2025-04-19T02:48:39.818Z"}
{"level":"error","message":"❌ C:\\Users\\atoda\\Documents\\Money_Mate\\BackEnd\\final_vm.py failed with code 1","timestamp":"2025-04-19T02:53:39.931Z"}
{"level":"error","message":"❌ Error running data processing scripts: C:\\Users\\atoda\\Documents\\Money_Mate\\BackEnd\\final_vm.py failed with code 1","stack":"Error: C:\\Users\\atoda\\Documents\\Money_Mate\\BackEnd\\final_vm.py failed with code 1\n    at ChildProcess.<anonymous> (C:\\Users\\atoda\\Documents\\Money_Mate\\BackEnd\\server.ts:61:23)\n    at ChildProcess.emit (node:events:518:28)\n    at ChildProcess.emit (node:domain:488:12)\n    at maybeClose (node:internal/child_process:1105:16)\n    at Process.ChildProcess._handle.onexit (node:internal/child_process:305:5)","timestamp":"2025-04-19T02:53:39.932Z"}
{"level":"error","timestamp":"2025-04-19T02:53:39.932Z"}
{"level":"error","message":"❌ C:\\Users\\atoda\\Documents\\Money_Mate\\BackEnd\\final_vm.py failed with code 1","timestamp":"2025-04-19T02:58:40.597Z"}
{"level":"error","message":"❌ Error running data processing scripts: C:\\Users\\atoda\\Documents\\Money_Mate\\BackEnd\\final_vm.py failed with code 1","stack":"Error: C:\\Users\\atoda\\Documents\\Money_Mate\\BackEnd\\final_vm.py failed with code 1\n    at ChildProcess.<anonymous> (C:\\Users\\atoda\\Documents\\Money_Mate\\BackEnd\\server.ts:61:23)\n    at ChildProcess.emit (node:events:518:28)\n    at ChildProcess.emit (node:domain:488:12)\n    at maybeClose (node:internal/child_process:1105:16)\n    at Process.ChildProcess._handle.onexit (node:internal/child_process:305:5)","timestamp":"2025-04-19T02:58:40.598Z"}
{"level":"error","timestamp":"2025-04-19T02:58:40.598Z"}
{"level":"error","message":"❌ C:\\Users\\atoda\\Documents\\Money_Mate\\BackEnd\\final_vm.py failed with code 1","timestamp":"2025-04-19T03:03:39.687Z"}
{"level":"error","message":"❌ Error running data processing scripts: C:\\Users\\atoda\\Documents\\Money_Mate\\BackEnd\\final_vm.py failed with code 1","stack":"Error: C:\\Users\\atoda\\Documents\\Money_Mate\\BackEnd\\final_vm.py failed with code 1\n    at ChildProcess.<anonymous> (C:\\Users\\atoda\\Documents\\Money_Mate\\BackEnd\\server.ts:61:23)\n    at ChildProcess.emit (node:events:518:28)\n    at ChildProcess.emit (node:domain:488:12)\n    at maybeClose (node:internal/child_process:1105:16)\n    at Process.ChildProcess._handle.onexit (node:internal/child_process:305:5)","timestamp":"2025-04-19T03:03:39.688Z"}
{"level":"error","timestamp":"2025-04-19T03:03:39.688Z"}
{"level":"error","message":"❌ C:\\Users\\atoda\\Documents\\Money_Mate\\BackEnd\\final_vm.py failed with code 1","timestamp":"2025-04-19T03:08:39.596Z"}
{"level":"error","message":"❌ Error running data processing scripts: C:\\Users\\atoda\\Documents\\Money_Mate\\BackEnd\\final_vm.py failed with code 1","stack":"Error: C:\\Users\\atoda\\Documents\\Money_Mate\\BackEnd\\final_vm.py failed with code 1\n    at ChildProcess.<anonymous> (C:\\Users\\atoda\\Documents\\Money_Mate\\BackEnd\\server.ts:61:23)\n    at ChildProcess.emit (node:events:518:28)\n    at ChildProcess.emit (node:domain:488:12)\n    at maybeClose (node:internal/child_process:1105:16)\n    at Process.ChildProcess._handle.onexit (node:internal/child_process:305:5)","timestamp":"2025-04-19T03:08:39.597Z"}
{"level":"error","timestamp":"2025-04-19T03:08:39.597Z"}
{"level":"error","message":"❌ C:\\Users\\atoda\\Documents\\Money_Mate\\BackEnd\\final_vm.py failed with code 1","timestamp":"2025-04-19T03:13:42.172Z"}
{"level":"error","message":"❌ Error running data processing scripts: C:\\Users\\atoda\\Documents\\Money_Mate\\BackEnd\\final_vm.py failed with code 1","stack":"Error: C:\\Users\\atoda\\Documents\\Money_Mate\\BackEnd\\final_vm.py failed with code 1\n    at ChildProcess.<anonymous> (C:\\Users\\atoda\\Documents\\Money_Mate\\BackEnd\\server.ts:61:23)\n    at ChildProcess.emit (node:events:518:28)\n    at ChildProcess.emit (node:domain:488:12)\n    at maybeClose (node:internal/child_process:1105:16)\n    at Process.ChildProcess._handle.onexit (node:internal/child_process:305:5)","timestamp":"2025-04-19T03:13:42.172Z"}
{"level":"error","timestamp":"2025-04-19T03:13:42.173Z"}
{"level":"error","message":"❌ C:\\Users\\atoda\\Documents\\Money_Mate\\BackEnd\\final_vm.py failed with code 1","timestamp":"2025-04-19T03:18:39.560Z"}
{"level":"error","message":"❌ Error running data processing scripts: C:\\Users\\atoda\\Documents\\Money_Mate\\BackEnd\\final_vm.py failed with code 1","stack":"Error: C:\\Users\\atoda\\Documents\\Money_Mate\\BackEnd\\final_vm.py failed with code 1\n    at ChildProcess.<anonymous> (C:\\Users\\atoda\\Documents\\Money_Mate\\BackEnd\\server.ts:61:23)\n    at ChildProcess.emit (node:events:518:28)\n    at ChildProcess.emit (node:domain:488:12)\n    at maybeClose (node:internal/child_process:1105:16)\n    at Process.ChildProcess._handle.onexit (node:internal/child_process:305:5)","timestamp":"2025-04-19T03:18:39.560Z"}
{"level":"error","timestamp":"2025-04-19T03:18:39.560Z"}
{"level":"error","message":"❌ C:\\Users\\atoda\\Documents\\Money_Mate\\BackEnd\\final_vm.py failed with code 1","timestamp":"2025-04-19T03:23:39.428Z"}
{"level":"error","message":"❌ Error running data processing scripts: C:\\Users\\atoda\\Documents\\Money_Mate\\BackEnd\\final_vm.py failed with code 1","stack":"Error: C:\\Users\\atoda\\Documents\\Money_Mate\\BackEnd\\final_vm.py failed with code 1\n    at ChildProcess.<anonymous> (C:\\Users\\atoda\\Documents\\Money_Mate\\BackEnd\\server.ts:61:23)\n    at ChildProcess.emit (node:events:518:28)\n    at ChildProcess.emit (node:domain:488:12)\n    at maybeClose (node:internal/child_process:1105:16)\n    at Process.ChildProcess._handle.onexit (node:internal/child_process:305:5)","timestamp":"2025-04-19T03:23:39.428Z"}
{"level":"error","timestamp":"2025-04-19T03:23:39.428Z"}
{"level":"error","message":"❌ C:\\Users\\atoda\\Documents\\Money_Mate\\BackEnd\\final_vm.py failed with code 1","timestamp":"2025-04-19T03:28:39.809Z"}
{"level":"error","message":"❌ Error running data processing scripts: C:\\Users\\atoda\\Documents\\Money_Mate\\BackEnd\\final_vm.py failed with code 1","stack":"Error: C:\\Users\\atoda\\Documents\\Money_Mate\\BackEnd\\final_vm.py failed with code 1\n    at ChildProcess.<anonymous> (C:\\Users\\atoda\\Documents\\Money_Mate\\BackEnd\\server.ts:61:23)\n    at ChildProcess.emit (node:events:518:28)\n    at ChildProcess.emit (node:domain:488:12)\n    at maybeClose (node:internal/child_process:1105:16)\n    at Process.ChildProcess._handle.onexit (node:internal/child_process:305:5)","timestamp":"2025-04-19T03:28:39.809Z"}
{"level":"error","timestamp":"2025-04-19T03:28:39.809Z"}
{"level":"error","message":"❌ C:\\Users\\atoda\\Documents\\Money_Mate\\BackEnd\\final_vm.py failed with code 1","timestamp":"2025-09-16T18:55:54.560Z"}
{"level":"error","message":"❌ Error running data processing scripts: C:\\Users\\atoda\\Documents\\Money_Mate\\BackEnd\\final_vm.py failed with code 1","stack":"Error: C:\\Users\\atoda\\Documents\\Money_Mate\\BackEnd\\final_vm.py failed with code 1\n    at ChildProcess.<anonymous> (C:\\Users\\atoda\\Documents\\Money_Mate\\BackEnd\\server.ts:61:23)\n    at ChildProcess.emit (node:events:518:28)\n    at ChildProcess.emit (node:domain:488:12)\n    at maybeClose (node:internal/child_process:1105:16)\n    at Process.ChildProcess._handle.onexit (node:internal/child_process:305:5)","timestamp":"2025-09-16T18:55:54.589Z"}
{"level":"error","timestamp":"2025-09-16T18:55:54.596Z"}
{"level":"error","message":"❌ C:\\Users\\atoda\\Documents\\Money_Mate\\BackEnd\\final_vm.py failed with code 1","timestamp":"2025-09-16T19:00:10.234Z"}
{"level":"error","message":"❌ Error running data processing scripts: C:\\Users\\atoda\\Documents\\Money_Mate\\BackEnd\\final_vm.py failed with code 1","stack":"Error: C:\\Users\\atoda\\Documents\\Money_Mate\\BackEnd\\final_vm.py failed with code 1\n    at ChildProcess.<anonymous> (C:\\Users\\atoda\\Documents\\Money_Mate\\BackEnd\\server.ts:61:23)\n    at ChildProcess.emit (node:events:518:28)\n    at ChildProcess.emit (node:domain:488:12)\n    at maybeClose (node:internal/child_process:1105:16)\n    at Process.ChildProcess._handle.onexit (node:internal/child_process:305:5)","timestamp":"2025-09-16T19:00:10.235Z"}
{"level":"error","timestamp":"2025-09-16T19:00:10.236Z"}
